{
	"candidate": "CVE-2014-0480",
	"description": "The core.urlresolvers.reverse function in Django before 1.4.14, 1.5.x before 1.5.9, 1.6.x before 1.6.6, and 1.7 before release candidate 3 does not properly validate URLs, which allows remote attackers to conduct phishing attacks via a // (slash slash) in a URL, which triggers a scheme-relative URL to be generated.",
	"priority": "low",
	"references": [
		"https://www.djangoproject.com/weblog/2014/aug/20/security/",
		"https://ubuntu.com/security/notices/USN-2347-1",
		"https://www.cve.org/CVERecord?id=CVE-2014-0480"
	],
	"assigned_to": "mdeslaur",
	"discovered_by": "Florian Apolloner",
	"public_date": "2014-08-26 14:55:00 UTC",
	"public_date_at_usn": "2014-08-26",
	"packages": {
		"devel": {
			"python-django": {
				"name": "python-django",
				"status": "not-affected",
				"note": "1.6.6-1",
				"patches": [
					{
						"source": "vendor",
						"text": "https://www.debian.org/security/2014/dsa-3010"
					},
					{
						"source": "upstream",
						"text": "https://github.com/django/django/commit/c2fe73133b62a1d9e8f7a6b43966570b14618d7e (1.4)"
					},
					{
						"source": "upstream",
						"text": "https://github.com/django/django/commit/da051da8df5e69944745072611351d4cfc6435d5 (1.6)"
					}
				]
			}
		},
		"lucid": {
			"python-django": {
				"name": "python-django",
				"status": "released",
				"note": "1.1.1-2ubuntu1.13",
				"patches": [
					{
						"source": "vendor",
						"text": "https://www.debian.org/security/2014/dsa-3010"
					},
					{
						"source": "upstream",
						"text": "https://github.com/django/django/commit/c2fe73133b62a1d9e8f7a6b43966570b14618d7e (1.4)"
					},
					{
						"source": "upstream",
						"text": "https://github.com/django/django/commit/da051da8df5e69944745072611351d4cfc6435d5 (1.6)"
					}
				]
			}
		},
		"precise": {
			"python-django": {
				"name": "python-django",
				"status": "released",
				"note": "1.3.1-4ubuntu1.12",
				"patches": [
					{
						"source": "vendor",
						"text": "https://www.debian.org/security/2014/dsa-3010"
					},
					{
						"source": "upstream",
						"text": "https://github.com/django/django/commit/c2fe73133b62a1d9e8f7a6b43966570b14618d7e (1.4)"
					},
					{
						"source": "upstream",
						"text": "https://github.com/django/django/commit/da051da8df5e69944745072611351d4cfc6435d5 (1.6)"
					}
				]
			}
		},
		"trusty": {
			"python-django": {
				"name": "python-django",
				"status": "released",
				"note": "1.6.1-2ubuntu0.4",
				"patches": [
					{
						"source": "vendor",
						"text": "https://www.debian.org/security/2014/dsa-3010"
					},
					{
						"source": "upstream",
						"text": "https://github.com/django/django/commit/c2fe73133b62a1d9e8f7a6b43966570b14618d7e (1.4)"
					},
					{
						"source": "upstream",
						"text": "https://github.com/django/django/commit/da051da8df5e69944745072611351d4cfc6435d5 (1.6)"
					}
				]
			}
		},
		"trusty/esm": {
			"python-django": {
				"name": "python-django",
				"status": "released",
				"note": "1.6.1-2ubuntu0.4",
				"patches": [
					{
						"source": "vendor",
						"text": "https://www.debian.org/security/2014/dsa-3010"
					},
					{
						"source": "upstream",
						"text": "https://github.com/django/django/commit/c2fe73133b62a1d9e8f7a6b43966570b14618d7e (1.4)"
					},
					{
						"source": "upstream",
						"text": "https://github.com/django/django/commit/da051da8df5e69944745072611351d4cfc6435d5 (1.6)"
					}
				]
			}
		},
		"upstream": {
			"python-django": {
				"name": "python-django",
				"status": "released",
				"note": "1.6.6-1",
				"patches": [
					{
						"source": "vendor",
						"text": "https://www.debian.org/security/2014/dsa-3010"
					},
					{
						"source": "upstream",
						"text": "https://github.com/django/django/commit/c2fe73133b62a1d9e8f7a6b43966570b14618d7e (1.4)"
					},
					{
						"source": "upstream",
						"text": "https://github.com/django/django/commit/da051da8df5e69944745072611351d4cfc6435d5 (1.6)"
					}
				]
			}
		}
	}
}
