{
	"candidate": "CVE-2024-39614",
	"description": "get_supported_language_variant() was subject to a potential denial-of-service attack when used with very long strings including a specific set of characters.",
	"notes": {
		"alexmurray": "upstream advises that only versions 4.2, 5.0 and 5.1 (plus main development branch) are affected but it is likely earlier versions may also be affected but upstream do not mention this as they are no longer maintained by them"
	},
	"priority": "medium",
	"references": [
		"https://www.cve.org/CVERecord?id=CVE-2024-39614"
	],
	"assigned_to": "mdeslaur",
	"discovered_by": "MProgrammer",
	"public_date": "2024-07-09 14:00:00 UTC",
	"crd": "2024-07-09 14:00:00 UTC",
	"packages": {
		"devel": {
			"python-django": {
				"name": "python-django",
				"status": "needs-triage"
			}
		},
		"esm-infra-legacy/trusty": {
			"python-django": {
				"name": "python-django",
				"status": "needs-triage"
			}
		},
		"esm-infra/bionic": {
			"python-django": {
				"name": "python-django",
				"status": "needs-triage"
			}
		},
		"esm-infra/xenial": {
			"python-django": {
				"name": "python-django",
				"status": "needs-triage"
			}
		},
		"focal": {
			"python-django": {
				"name": "python-django",
				"status": "needs-triage"
			}
		},
		"jammy": {
			"python-django": {
				"name": "python-django",
				"status": "needs-triage"
			}
		},
		"mantic": {
			"python-django": {
				"name": "python-django",
				"status": "needs-triage"
			}
		},
		"noble": {
			"python-django": {
				"name": "python-django",
				"status": "needs-triage"
			}
		},
		"trusty/esm": {
			"python-django": {
				"name": "python-django",
				"status": "needs-triage"
			}
		},
		"upstream": {
			"python-django": {
				"name": "python-django",
				"status": "needs-triage"
			}
		}
	}
}
