{
  "candidate": "CVE-2022-1431",
  "description": "An issue has been discovered in GitLab affecting all versions starting from 12.10 before 14.8.6, all versions starting from 14.9 before 14.9.4, all versions starting from 14.10 before 14.10.1. GitLab was not correctly handling malicious requests to the PyPi API endpoint allowing the attacker to cause uncontrolled resource consumption.",
  "priority": "medium",
  "cvss": {
    "nvd": " CVSS:3.1/AV:N/AC:L/PR:N/UI:N/S:U/C:N/I:N/A:L [5.3 MEDIUM]"
  },
  "references": [
    "https://cve.mitre.org/cgi-bin/cvename.cgi?name=CVE-2022-1431",
    "https://hackerone.com/reports/996850",
    "https://gitlab.com/gitlab-org/cves/-/blob/master/2022/CVE-2022-1431.json",
    "https://gitlab.com/gitlab-org/gitlab/-/issues/262724"
  ],
  "public_date": "2022-05-10 21:15:00 UTC",
  "packages": {
    "upstream": {
      "gitlab": {
        "name": "gitlab",
        "status": "needs-triage"
      }
    }
  }
}
